Workbook

Sheet Graphique
C5: Code Minier_2003 | D5: Code Minier_2015 | E5: Droit Commun | F5: Guinée 2011
B6: Etat | C6: 0.49379191 | D6: 0.60766343 | E6: 0.67665692 | F6: 0.66462504
B7: Endeavour Mining | C7: 0.50620809 | D7: 0.39233657 | E7: 0.32334308 | F7: 0.33537496
B17: Année | C17: 2011 | D17: 2012 | E17: 2013 | F17: 2014 | G17: 2015 | H17: 2016 | I17: 2017 | J17: 2018 | K17: 2019 | L17: 2020 | M17: 2021
B18: Cash flow avant impôt | C18: =C20/1000 -> -73445.792 | D18: =D20/1000 -> -241407.82 | E18: =E20/1000 -> 116802.04 | F18: =F20/1000 -> 141544.2 | G18: =G20/1000 -> 93764.638 | H18: =H20/1000 -> 55567.633 | I18: =I20/1000 -> 110004.64 | J18: =J20/1000 -> 77958.596 | ... M18: =M20/1000 -> 141930.05
B19: Cash flow après impôt | C19: =C21/1000 -> -73808.871 | D19: =D21/1000 -> -241760.75 | E19: =E21/1000 -> 90770.113 | F19: =F21/1000 -> 103094.14 | G19: =G21/1000 -> 71085.597 | H19: =H21/1000 -> 43835.694 | I19: =I21/1000 -> 75540.704 | J19: =J21/1000 -> 54117.593 | ... M19: =M21/1000 -> 98672.88
B20: Cash flow avant impôt | C20: -73445792 | D20: -241407817 | E20: 116802045 | F20: 141544202 | G20: 93764638 | H20: 55567633 | I20: 110004643 | J20: 77958596 | K20: 63568427 | L20: 97578084 | M20: 141930048
B21: Cash flow après impôt | C21: -73808871 | D21: -2.4176075e+08 | E21: 90770113 | F21: 1.0309414e+08 | G21: 71085597 | H21: 43835694 | I21: 75540704 | J21: 54117593 | K21: 45531853 | L21: 68247922 | M21: 98672880
B29: Composition du TEMI
C30: Composition du TEMI | D30: Montant total
B31: Redevance superficiaire | C31: =D31/D37 -> 0.0087984768 | D31: =SUM('Modèle de base (CM 2003)'!C33:M33) -> 4823469.2
B32: Droits fixes | C32: =D32/D37 -> 1.8499741e-05 | D32: ='Modèle de base (CM 2003)'!C29 -> 10141.861
B33: Impôts sur les sociétés (IS/IMF) | C33: =D33/D37 -> 0.62780272 | D33: =SUM('Modèle de base (CM 2003)'!C44:M44) -> 3.4417175e+08
B34: Redevance proportionnelle | C34: =D34/D37 -> 0.18120541 | D34: =SUM('Modèle de base (CM 2003)'!C37:M37) -> 99339776
B35: Dividende de l'Etat | C35: =D35/D37 -> 0.11659193 | D35: =SUM('Modèle de base (CM 2003)'!C48:M48) -> 63917610
B36: Impôt sur les dividendes | C36: =D36/D37 -> 0.065582963 | D36: =SUM('Modèle de base (CM 2003)'!C50:M50) -> 35953656
B37: Recettes totales de l'Etat | C37: =SUM(C31:C36) -> 1 | D37: =SUM(D31:D36) -> 5.482164e+08
B43: Prix de l'or | C43: 1100 | D43: 1300 | E43: 1600
B44: TEMI_CM 2003 | C44: =Récapitulatif!C23 -> 0.81343486 | D44: =Récapitulatif!D23 -> 0.49379191 | E44: =Récapitulatif!E23 -> 0.41493617
B47: Prix de l'or | C47: 1100 | D47: 1300 | E47: 1600
B48: TEMI_CM 2015 | C48: =Récapitulatif!C36 -> 0.98881004 | D48: =Récapitulatif!D36 -> 0.60766343 | E48: =Récapitulatif!E36 -> 0.51578801
C61: Flux net de trésorerie avant impôt | D61: ='Modèle de base (CM 2003)'!C25 -> -73445792 | E61: ='Modèle de base (CM 2003)'!D25 -> -241407817 | F61: ='Modèle de base (CM 2003)'!E25 -> 174154845 | G61: ='Modèle de base (CM 2003)'!F25 -> 206115602 | H61: ='Modèle de base (CM 2003)'!G25 -> 150706738 | I61: ='Modèle de base (CM 2003)'!H25 -> 106065133 | J61: ='Modèle de base (CM 2003)'!I25 -> 173295943 | K61: ='Modèle de base (CM 2003)'!J25 -> 128268596 | ... N61: ='Modèle de base (CM 2003)'!M25 -> 177741048
C62: Revenu de l'Etat | D62: ='Modèle de base (CM 2003)'!C53 -> 363078.64 | E62: ='Modèle de base (CM 2003)'!D53 -> 352936.77 | F62: ='Modèle de base (CM 2003)'!E53 -> 60834890 | G62: ='Modèle de base (CM 2003)'!F53 -> 82096586 | H62: ='Modèle de base (CM 2003)'!G53 -> 55693081 | I62: ='Modèle de base (CM 2003)'!H53 -> 36861266 | J62: ='Modèle de base (CM 2003)'!I53 -> 75618286 | K62: ='Modèle de base (CM 2003)'!J53 -> 54780665 | ... N62: ='Modèle de base (CM 2003)'!M53 -> 77871841
C63: Profit de l'investisseur | F63: ='Modèle de base (CM 2003)'!E49 -> 62503669 | G63: ='Modèle de base (CM 2003)'!F49 -> 88053202 | H63: ='Modèle de base (CM 2003)'!G49 -> 55955953 | I63: ='Modèle de base (CM 2003)'!H49 -> 33188013 | J63: ='Modèle de base (CM 2003)'!I49 -> 79861929 | K63: ='Modèle de base (CM 2003)'!J49 -> 56454445 | L63: ='Modèle de base (CM 2003)'!K49 -> 43168178 | M63: ='Modèle de base (CM 2003)'!L49 -> 66001674 | N63: ='Modèle de base (CM 2003)'!M49 -> 90071426
C64: Investissement | D64: ='Modèle de base (CM 2003)'!C23*(-1) -> -73445792 | E64: ='Modèle de base (CM 2003)'!D23*(-1) -> -241407817
C65: Coût de production | F65: ='Modèle de base (CM 2003)'!E23 -> 131726755 | G65: ='Modèle de base (CM 2003)'!F23 -> 138265198 | H65: ='Modèle de base (CM 2003)'!G23 -> 152984462 | I65: ='Modèle de base (CM 2003)'!H23 -> 163254867 | J65: ='Modèle de base (CM 2003)'!I23 -> 164257657 | K65: ='Modèle de base (CM 2003)'!J23 -> 140051404 | L65: ='Modèle de base (CM 2003)'!K23 -> 114270273 | M65: ='Modèle de base (CM 2003)'!L23 -> 101059316 | N65: ='Modèle de base (CM 2003)'!M23 -> 13250952
C66: Coût de rehabilitation
B86: Recettes totales | D86: =SUM('Code Minier 2015'!C54:M54) -> 3.0613969e+08
B87: Redevance proportionnelles | D87: =SUM('Code Minier 2015'!C37:M37) -> 80713568
B88: Fonds de développement local (1%) | D88: =SUM('Code Minier 2015'!E40:M40) -> 20178392
B89: Fonds de développement local total | C89: =D89/D86 -> 0.11864226 | D89: =D88+(D87*20%) -> 36321106
B90: Etat central | C90: =D90/D86 -> 0.88135774 | D90: =D86-D89 -> 2.6981858e+08
C104: Tri avant impôt | D104: ='Modèle de base (CM 2003)'!E27 -> -0.3913088 | E104: ='Modèle de base (CM 2003)'!F27 -> 0.11243079 | F104: ='Modèle de base (CM 2003)'!G27 -> 0.2768997 | G104: ='Modèle de base (CM 2003)'!H27 -> 0.3407976 | H104: ='Modèle de base (CM 2003)'!I27 -> 0.40012659 | I104: ='Modèle de base (CM 2003)'!J27 -> 0.42540794 | J104: ='Modèle de base (CM 2003)'!K27 -> 0.43824983 | K104: ='Modèle de base (CM 2003)'!L27 -> 0.44942432 | L104: ='Modèle de base (CM 2003)'!M27 -> 0.45818507
C105: Tri après impôt_CM 2003 | E105: ='Modèle de base (CM 2003)'!F57 -> -0.1492555 | F105: ='Modèle de base (CM 2003)'!G57 -> 0.024126629 | G105: ='Modèle de base (CM 2003)'!H57 -> 0.10169092 | H105: ='Modèle de base (CM 2003)'!I57 -> 0.17018122 | I105: ='Modèle de base (CM 2003)'!J57 -> 0.20296263 | J105: ='Modèle de base (CM 2003)'!K57 -> 0.2221153 | K105: ='Modèle de base (CM 2003)'!L57 -> 0.23986363 | L105: ='Modèle de base (CM 2003)'!M57 -> 0.2547242
C106: Tri après impôt_CM 2015 | E106: ='Code Minier 2015'!F58 -> -0.274356 | F106: ='Code Minier 2015'!G58 -> -0.1096526 | G106: ='Code Minier 2015'!H58 -> -0.037981949 | H106: ='Code Minier 2015'!I58 -> 0.039866811 | I106: ='Code Minier 2015'!J58 -> 0.077305814 | J106: ='Code Minier 2015'!K58 -> 0.10075814 | K106: ='Code Minier 2015'!L58 -> 0.12587439 | L106: ='Code Minier 2015'!M58 -> 0.15060915
C117: Cours de l'Or | D117: 1100 | E117: 1300 | F117: 1600
C118: TEMI | D118: 1.0867363 | E118: 0.60766343 | F118: 0.49941613
C119: TRI | D119: 0.13994104 | E119: 0.27738179 | F119: 0.45818507

Sheet Récapitulatif
B1: Code minier de 2003 | D1: Code minier de 2015
B2: Phase préparatoire | C2: Phase de production | D2: Phase préparatoire | E2: Phase de production | I2: Mine | J2: HOUNDE
A3: Durée du titre | B3: 20 ans | D3: idem | I3: Investisseur | J3: ENDEAVOUR MINING
A4: Renouvellement | B4: 5 ans | D4: idem | I4: Date d'octroi du permis d'exploitation | J4: 42040
A5: Part de l'Etat | B5: 0.1 | D5: idem | I5: Date de signature de la convention | J5: 42338
A6: Redevances fixes | B6: 5 millions de FCFA | C6: 0 | D6: idem | E6: idem | I6: Début probable de la production | J6: 21 mois la signature de la convention
A7: Redevances superficiaires | B7: 0 | C7: 7,5 millions années 1 à 5; 10 millions années 6 à 10 et 15 millions après | D7: idem | E7: idem | I7: Durée d'exploitation | J7: 11 ans
A8: Redevances proportionnelles | B8: 0 | D8: idem | E8: idem | I8: Superficie de la mine | J8: 23,2 km2
A9: Fonds de développement local | E9: Investisseur 1% du chiffres d'affaires | I9: Teneur moyenne en g/t | J9: 1.97
A10: Réhabilitation | B10: Investisseur | D10: Idem | I10: Produtction en koz | J10: 172464.89
A11: Impot sur les sociétés | B11: Exonération | C11: Taux de droit commun réduit de 10 points | D11: idem | E11: Taux de droit commun
A12: IMF | B12: Exonération | C12: Exonération pendant 7 ans ou moitié de la durée d'exploitation | D12: idem | E12: idem
A13: Patente, TPA, TBM | B13: Exonération | C13: Exonération pendant 7 ans ou moitié de la durée d'exploitation | D13: idem | E13: idem | K13: Synthèse de l'évaluation du système fiscal
A14: Droits et taxes de douanes | B14: 0.025 | C14: 0.075 | D14: idem | E14: idem | K14: Critères | L14: Niveau | M14: Acteur concerné
K15: Efficacité | M15: Etat
C16: Taux d'actualisation 5% | F16: Taux d'actualisation 10% | I16: Elasticité du TEMI par rapport au TRI | K16: Progessivité | M16: Etat
B17: Cours de l'Or | C17: 1100 | D17: 1300 | E17: 1600 | F17: 1100 | G17: 1300 | H17: 1600 | K17: Transparence | M17: Etat
A18: Avant impôts | B18: VAN | C18: 1.3182213e+08 | D18: 3.5817536e+08 | E18: 6.9770521e+08 | F18: 45127855 | G18: 2.1488259e+08 | H18: 4.695147e+08 | K18: Partage de risque | M18: Etat
B19: TRI | C19: 0.13994104 | D19: 0.27738179 | E19: 0.45818507 | F19: 0.13994104 | G19: 0.27738179 | H19: 0.45818507 | K19: Développement local | M19: Etat
K20: Environnement | M20: Etat
A21: Après impôts | B21: VAN | C21: 24593413 | D21: 1.8131126e+08 | E21: 4.0820208e+08 | F21: -32756435 | G21: 84810341 | H21: 2.5496825e+08 | K21: Génération futures | M21: Etat
B22: TRI | C22: 0.068429663 | D22: 0.1760666 | E22: 0.31152275 | F22: 0.068429663 | G22: 0.1760666 | H22: 0.31152275 | K22: Lutte optimisation | M22: Etat
B23: TEMI | C23: 0.81343486 | D23: 0.49379191 | E23: 0.41493617 | F23: 1.7258584 | G23: 0.60531777 | H23: 0.45695365 | I23: =((H23-G23)/G23)/((H22-G22)/G22) -> -0.31858384 | K23: Neutralité | M23: Investisseur
C29: Taux d'actualisation 5% | F29: Taux d'actualisation 10% | I29: Elasticité du TEMI par rapport au TRI
B30: Cours de l'Or | C30: 1100 | D30: 1300 | E30: 1600 | F30: 1100 | G30: 1300 | H30: 1600
A31: Avant impôts | B31: VAN | C31: 1.3182213e+08 | D31: 3.5817536e+08 | E31: 6.9770521e+08 | F31: 45127855 | G31: 2.1488259e+08 | H31: 4.695147e+08
B32: TRI | C32: 0.13994104 | D32: 0.27738179 | E32: 0.45818507 | F32: 0.13994104 | G32: 0.27738179 | H32: 0.45818507
A34: Après impôts | B34: VAN | C34: 1475084.9 | D34: 1.4052529e+08 | E34: 3.3783723e+08 | F34: -49384053 | G34: 54946110 | H34: 2.0292118e+08
B35: TRI | C35: 0.051137873 | D35: 0.15060915 | E35: 0.27309616 | F35: 0.051137873 | G35: 0.15060915 | H35: 0.27309616
B36: TEMI | C36: 0.98881004 | D36: 0.60766343 | E36: 0.51578801 | F36: 2.0943142 | G36: 0.74429707 | H36: 0.56780654 | I36: =((H36-G36)/G36)/((H35-G35)/G35) -> -0.29156567
C43: Taux d'actualisation 5% | F43: Taux d'actualisation 10%
B44: Cours de l'Or | C44: 1100 | D44: 1300 | E44: 1600 | F44: 1100 | G44: 1300 | H44: 1600
A45: Avant impôts | B45: VAN | C45: 1.3182213e+08 | D45: 3.5817536e+08 | E45: 6.9770521e+08 | F45: 45127855 | G45: 2.1488259e+08 | H45: 4.695147e+08
B46: TRI | C46: 0.13994104 | D46: 0.27738179 | E46: 0.45818507 | F46: 0.13994104 | G46: 0.27738179 | H46: 0.45818507
A48: Après impôts | B48: VAN | C48: -11433766 | D48: 1.4052529e+08 | E48: 3.4925998e+08 | F48: -58555691 | G48: 52487256 | H48: 2.1198881e+08
B49: TRI | C49: 0.041002242 | D49: 0.15060915 | E49: 0.28111476 | F49: 0.041002242 | G49: 0.1487911 | H49: 0.28111476
B50: TEMI | C50: 1.0867363 | D50: 0.60766343 | E50: 0.49941613 | F50: 2.2975509 | G50: 0.75573985 | H50: 0.54849378

Sheet Modèle de base (CM 2003)
A1: Projet aurifère_De Houndé | B1: Unités | C1: 2011 | D1: 2012 | E1: 2013 | F1: 2014 | G1: 2015 | H1: 2016 | I1: 2017 | J1: 2018 | K1: 2019 | L1: 2020 | M1: 2021
A4: Production
A5: Quantité Traité | B5: t
A6: Teneur en or | B6: g/t
A7: Quantité d'Or Récupéré | B7: oz | E7: 191176 | F7: 215238 | G7: 189807 | H7: 168325 | I7: 210971 | J7: 167700 | K7: 136799 | L7: 152798 | M7: 119370 | N7: =AVERAGE(E7:M7) -> 172464.89 | Q7: Données | R7: VAN AV IMPÔT | S7: VAN AP IMPÔT | T7: TEMI | U7: TRI AV | V7: TRI AP
A8: Cours de l'or | B8: =Q8 -> 1600 | E8: 1300 | F8: 1300 | G8: 1300 | H8: 1300 | I8: 1300 | J8: 1300 | K8: 1300 | L8: 1300 | M8: 1300 | P8: Cours de l'or | Q8: 1600 | R8: =C26 -> 6.9770521e+08 | S8: =C55 -> 3.0445938e+08 | T8: =C56 -> 0.56362749 | U8: =C27 -> 0.45818507 | V8: =C57 -> 0.2547242
A9: Chiffre d'Affaire | B9: $ | E9: =E7*$B$8 -> 305881600 | F9: =F7*$B$8 -> 344380800 | G9: =G7*$B$8 -> 303691200 | H9: =H7*$B$8 -> 269320000 | I9: =I7*$B$8 -> 337553600 | J9: =J7*$B$8 -> 268320000 | K9: =K7*$B$8 -> 218878400 | L9: =L7*$B$8 -> 244476800 | M9: =M7*$B$8 -> 190992000 | P9: Taux d'actualisation | Q9: 0.05
A10: Taux de change | B10: 493.00615 | P10: IS | Q10: 0.35
A11: Taux d'actualisation | B11: =Q9 -> 0.05 | P11: Taux de redevance propotionelle | Q11: 0.04
A13: Coûts d'investissement (CAPEX)
A14: Coûts des construction industrielles | B14: $ | C14: 49760265 | D14: 116107284
A15: Coûts des biens d'équipement | C15: 23685527 | D15: 125300533 | E15: 11632917 | F15: 3722927 | G15: 18272647 | H15: 4482500 | I15: 2137128 | J15: 1103055 | K15: 4934651 | L15: 2727670 | M15: 542926
A16: Autres depenses | B16: $ | C16: 0 | D16: 0 | E16: 1595000 | F16: 2708200 | G16: 249700 | H16: 2581553 | I16: 469553 | J16: 3654542 | K16: 249700 | L16: 106700 | M16: 0
A17: Coûts de réhabilitation du site | B17: $ | E17: 2830244 | F17: 3314368 | G17: 3215137 | H17: 3842412 | I17: 4018506 | J17: 2935298 | K17: 1813443 | L17: 1249254 | M17: 3165512
A18: TOTAL CAPITAL | B18: $ | C18: =SUM(C14:C17) -> 73445792 | D18: =SUM(D14:D17) -> 241407817 | E18: =SUM(E14:E17) -> 16058161 | F18: =SUM(F14:F17) -> 9745495 | G18: =SUM(G14:G17) -> 21737484 | H18: =SUM(H14:H17) -> 10906465 | I18: =SUM(I14:I17) -> 6625187 | J18: =SUM(J14:J17) -> 7692895 | ... M18: =SUM(M14:M17) -> 3708438
A20: Coûts d'exploitation (Opex)/hors redevance | B20: $ | C20: 0 | D20: 0 | E20: 115668594 | F20: 128519703 | G20: 131246978 | H20: 152348402 | I20: 157632470 | J20: 132358509 | K20: 107272479 | L20: 96975692 | M20: 9542514
A21: Coûts d'exploitation moyen (Opex) /hors redevance | B21: $/oz | E21: =E20/E7 -> 605.03721 | F21: =F20/F7 -> 597.10508 | G21: =G20/G7 -> 691.47596 | H21: =H20/H7 -> 905.08482 | I21: =I20/I7 -> 747.17601 | J21: =J20/J7 -> 789.25766 | K21: =K20/K7 -> 784.16128 | L21: =L20/L7 -> 634.66598 | M21: =M20/M7 -> 79.940638
A23: Coût Totaux | C23: =C18+C20 -> 73445792 | D23: =D18+D20 -> 241407817 | E23: =E18+E20 -> 131726755 | F23: =F18+F20 -> 138265198 | G23: =G18+G20 -> 152984462 | H23: =H18+H20 -> 163254867 | I23: =I18+I20 -> 164257657 | J23: =J18+J20 -> 140051404 | ... M23: =M18+M20 -> 13250952
A25: Cash-flows avant impôts | C25: =C9-C23 -> -73445792 | D25: =D9-D23 -> -241407817 | E25: =E9-E23 -> 174154845 | F25: =F9-F23 -> 206115602 | G25: =G9-G23 -> 150706738 | H25: =H9-H23 -> 106065133 | I25: =I9-I23 -> 173295943 | J25: =J9-J23 -> 128268596 | ... M25: =M9-M23 -> 177741048
A26: VAN avant impôts | C26: =NPV($B$11,C25:M25) -> 6.9770521e+08
A27: TRI avant impôts | C27: =IRR(C25:M25) -> 0.45818507 | E27: =IRR($C$25:E25) -> -0.3913088 | F27: =IRR($C$25:F25) -> 0.11243079 | G27: =IRR($C$25:G25) -> 0.2768997 | H27: =IRR($C$25:H25) -> 0.3407976 | I27: =IRR($C$25:I25) -> 0.40012659 | J27: =IRR($C$25:J25) -> 0.42540794 | K27: =IRR($C$25:K25) -> 0.43824983 | L27: =IRR($C$25:L25) -> 0.44942432 | M27: =IRR($C$25:M25) -> 0.45818507
A29: Droits fixes | B29: 5000000 | C29: =B29/B10 -> 10141.861
A32: Superficie de la mine | C32: 23.2 | D32: 23.2 | E32: 23.2 | F32: 23.2 | G32: 23.2 | H32: 23.2 | I32: 23.2 | J32: 23.2 | K32: 23.2 | L32: 23.2 | M32: 23.2
A33: Redevance superficière | C33: =('Données fiscales'!C58/'Modèle de base (CM 2003)'!$B$10)*'Modèle de base (CM 2003)'!C32 -> 352936.77 | D33: =('Données fiscales'!D58/'Modèle de base (CM 2003)'!$B$10)*'Modèle de base (CM 2003)'!D32 -> 352936.77 | E33: =('Données fiscales'!E58/'Modèle de base (CM 2003)'!$B$10)*'Modèle de base (CM 2003)'!E32 -> 352936.77 | F33: =('Données fiscales'!F58/'Modèle de base (CM 2003)'!$B$10)*'Modèle de base (CM 2003)'!F32 -> 352936.77 | G33: =('Données fiscales'!G58/'Modèle de base (CM 2003)'!$B$10)*'Modèle de base (CM 2003)'!G32 -> 352936.77 | H33: =('Données fiscales'!H58/'Modèle de base (CM 2003)'!$B$10)*'Modèle de base (CM 2003)'!H32 -> 470582.36 | I33: =('Données fiscales'!I58/'Modèle de base (CM 2003)'!$B$10)*'Modèle de base (CM 2003)'!I32 -> 470582.36 | J33: =('Données fiscales'!J58/'Modèle de base (CM 2003)'!$B$10)*'Modèle de base (CM 2003)'!J32 -> 470582.36 | ... M33: =('Données fiscales'!M58/'Modèle de base (CM 2003)'!$B$10)*'Modèle de base (CM 2003)'!M32 -> 705873.55
A35: Redevance proportionnelle
A36: taux de la redevance | B36: =Q11 -> 0.04 | E36: ='Données fiscales'!E59 -> 0.04 | F36: ='Données fiscales'!F59 -> 0.04 | G36: ='Données fiscales'!G59 -> 0.04 | H36: ='Données fiscales'!H59 -> 0.04 | I36: ='Données fiscales'!I59 -> 0.04 | J36: ='Données fiscales'!J59 -> 0.04 | K36: ='Données fiscales'!K59 -> 0.04 | L36: ='Données fiscales'!L59 -> 0.04 | M36: ='Données fiscales'!M59 -> 0.04
A37: Montant de la redevance | C37: =$B$36*C9 -> 0 | D37: =$B$36*D9 -> 0 | E37: =$B$36*E9 -> 12235264 | F37: =$B$36*F9 -> 13775232 | G37: =$B$36*G9 -> 12147648 | H37: =$B$36*H9 -> 10772800 | I37: =$B$36*I9 -> 13502144 | J37: =$B$36*J9 -> 10732800 | ... M37: =$B$36*M9 -> 7639680
A39: Charges d'amortissement | C39: =Amortissement!C122 -> 14450237 | D39: =Amortissement!D122 -> 72391495 | E39: =Amortissement!E122 -> 54722766 | F39: =Amortissement!F122 -> 41469139 | G39: =Amortissement!G122 -> 42554951 | H39: =Amortissement!H122 -> 38090104 | I39: =Amortissement!I122 -> 22807098 | J39: =Amortissement!J122 -> 20561890 | ... M39: =Amortissement!M122 -> 15427244
A41: Bénéfice imposable | C41: =C$9-(C$23+C$29+C$33+C$37+C$39) -> -88259108 | D41: =D$9-(D$23+D$29+D$33+D$37+D$39) -> -3.1415225e+08 | E41: =E$9-(E$23+E$29+E$33+E$37+E$39) -> 1.0684388e+08 | F41: =F$9-(F$23+F$29+F$33+F$37+F$39) -> 1.5051829e+08 | G41: =G$9-(G$23+G$29+G$33+G$37+G$39) -> 95651203 | H41: =H$9-(H$23+H$29+H$33+H$37+H$39) -> 56731646 | I41: =I$9-(I$23+I$29+I$33+I$37+I$39) -> 1.3651612e+08 | J41: =J$9-(J$23+J$29+J$33+J$37+J$39) -> 96503324 | ... M41: =M$9-(M$23+M$29+M$33+M$37+M$39) -> 1.5396825e+08
A42: Taux IS | B42: =Q10 -> 0.35 | E42: ='Données fiscales'!E35 -> 0.175 | F42: ='Données fiscales'!F35 -> 0.175 | G42: ='Données fiscales'!G35 -> 0.175 | H42: ='Données fiscales'!H35 -> 0.175 | I42: ='Données fiscales'!I35 -> 0.175 | J42: ='Données fiscales'!J35 -> 0.175 | K42: ='Données fiscales'!K35 -> 0.175 | L42: ='Données fiscales'!L35 -> 0.175 | M42: ='Données fiscales'!M35 -> 0.175
A43: Montant IMF | J43: =0.5%*J9 -> 1341600 | K43: =0.5%*K9 -> 1094392 | L43: =0.5%*L9 -> 1222384 | M43: =0.5%*M9 -> 954960
A44: IS/IMF | C44: =IF(C$41*$B$42>C$43,C$41*$B$42,C$43) -> 0 | D44: =IF(D$41*$B$42>D$43,D$41*$B$42,D$43) -> 0 | E44: =IF(E$41*$B$42>E$43,E$41*$B$42,E$43) -> 37395358 | F44: =IF(F$41*$B$42>F$43,F$41*$B$42,F$43) -> 52681403 | G44: =IF(G$41*$B$42>G$43,G$41*$B$42,G$43) -> 33477921 | H44: =IF(H$41*$B$42>H$43,H$41*$B$42,H$43) -> 19856076 | I44: =IF(I$41*$B$42>I$43,I$41*$B$42,I$43) -> 47780641 | J44: =IF(J$41*$B$42>J$43,J$41*$B$42,J$43) -> 33776163 | ... M44: =IF(M$41*$B$42>M$43,M$41*$B$42,M$43) -> 53888888
A46: Résultat après impôt | C46: =C41-C44 -> -88259108 | D46: =D41-D44 -> -3.1415225e+08 | E46: =E41-E44 -> 69448521 | F46: =F41-F44 -> 97836891 | G46: =G41-G44 -> 62173282 | H46: =H41-H44 -> 36875570 | I46: =I41-I44 -> 88735477 | J46: =J41-J44 -> 62727161 | ... M46: =M41-M44 -> 1.0007936e+08
A47: Participation de l'Etat | B47: 0.1
A48: Dividende de l'Etat | C48: =IF(C46>0,C46*$B$47,0) -> 0 | D48: =IF(D46>0,D46*$B$47,0) -> 0 | E48: =IF(E46>0,E46*$B$47,0) -> 6944852.1 | F48: =IF(F46>0,F46*$B$47,0) -> 9783689.1 | G48: =IF(G46>0,G46*$B$47,0) -> 6217328.2 | H48: =IF(H46>0,H46*$B$47,0) -> 3687557 | I48: =IF(I46>0,I46*$B$47,0) -> 8873547.7 | J48: =IF(J46>0,J46*$B$47,0) -> 6272716.1 | ... M48: =IF(M46>0,M46*$B$47,0) -> 10007936
A49: Part de la société | C49: =C46-C48 -> -88259108 | D49: =D46-D48 -> -3.1415225e+08 | E49: =E46-E48 -> 62503669 | F49: =F46-F48 -> 88053202 | G49: =G46-G48 -> 55955953 | H49: =H46-H48 -> 33188013 | I49: =I46-I48 -> 79861929 | J49: =J46-J48 -> 56454445 | ... M49: =M46-M48 -> 90071426
A50: Impôt sur les dividendes | C50: =IF(C49>0,C49*'Données fiscales'!C40,0) -> 0 | D50: =IF(D49>0,D49*'Données fiscales'!D40,0) -> 0 | E50: =IF(E49>0,E49*'Données fiscales'!E40,0) -> 3906479.3 | F50: =IF(F49>0,F49*'Données fiscales'!F40,0) -> 5503325.1 | G50: =IF(G49>0,G49*'Données fiscales'!G40,0) -> 3497247.1 | H50: =IF(H49>0,H49*'Données fiscales'!H40,0) -> 2074250.8 | I50: =IF(I49>0,I49*'Données fiscales'!I40,0) -> 4991370.6 | J50: =IF(J49>0,J49*'Données fiscales'!J40,0) -> 3528402.8 | ... M50: =IF(M49>0,M49*'Données fiscales'!M40,0) -> 5629464.1
A53: Recettes totales de l'Etat | C53: =C$29+C$33+C$37+C$44+C$48+C$50 -> 363078.64 | D53: =D$29+D$33+D$37+D$44+D$48+D$50 -> 352936.77 | E53: =E$29+E$33+E$37+E$44+E$48+E$50 -> 60834890 | F53: =F$29+F$33+F$37+F$44+F$48+F$50 -> 82096586 | G53: =G$29+G$33+G$37+G$44+G$48+G$50 -> 55693081 | H53: =H$29+H$33+H$37+H$44+H$48+H$50 -> 36861266 | I53: =I$29+I$33+I$37+I$44+I$48+I$50 -> 75618286 | J53: =J$29+J$33+J$37+J$44+J$48+J$50 -> 54780665 | ... M53: =M$29+M$33+M$37+M$44+M$48+M$50 -> 77871841
A54: Cash-Flows après imôts | C54: =C25-C53 -> -73808871 | D54: =D25-D53 -> -2.4176075e+08 | E54: =E25-E53 -> 1.1331996e+08 | F54: =F25-F53 -> 1.2401902e+08 | G54: =G25-G53 -> 95013657 | H54: =H25-H53 -> 69203867 | I54: =I25-I53 -> 97677657 | J54: =J25-J53 -> 73487931 | ... M54: =M25-M53 -> 99869207
A55: VAN après impôts | C55: =NPV($B$11,C54:M54) -> 3.0445938e+08
...

Sheet Code Minier 2015
A1: Projet aurifère_De Houndé | B1: Unités | C1: ='Modèle de base (CM 2003)'!C1 -> 2011 | D1: ='Modèle de base (CM 2003)'!D1 -> 2012 | E1: ='Modèle de base (CM 2003)'!E1 -> 2013 | F1: ='Modèle de base (CM 2003)'!F1 -> 2014 | G1: ='Modèle de base (CM 2003)'!G1 -> 2015 | H1: ='Modèle de base (CM 2003)'!H1 -> 2016 | I1: ='Modèle de base (CM 2003)'!I1 -> 2017 | J1: ='Modèle de base (CM 2003)'!J1 -> 2018 | ... M1: ='Modèle de base (CM 2003)'!M1 -> 2021
C2: ='Modèle de base (CM 2003)'!C2 -> 0 | D2: ='Modèle de base (CM 2003)'!D2 -> 0 | E2: ='Modèle de base (CM 2003)'!E2 -> 0 | F2: ='Modèle de base (CM 2003)'!F2 -> 0 | G2: ='Modèle de base (CM 2003)'!G2 -> 0 | H2: ='Modèle de base (CM 2003)'!H2 -> 0 | I2: ='Modèle de base (CM 2003)'!I2 -> 0 | J2: ='Modèle de base (CM 2003)'!J2 -> 0 | ... M2: ='Modèle de base (CM 2003)'!M2 -> 0
C3: ='Modèle de base (CM 2003)'!C3 -> 0 | D3: ='Modèle de base (CM 2003)'!D3 -> 0 | E3: ='Modèle de base (CM 2003)'!E3 -> 0 | F3: ='Modèle de base (CM 2003)'!F3 -> 0 | G3: ='Modèle de base (CM 2003)'!G3 -> 0 | H3: ='Modèle de base (CM 2003)'!H3 -> 0 | I3: ='Modèle de base (CM 2003)'!I3 -> 0 | J3: ='Modèle de base (CM 2003)'!J3 -> 0 | ... M3: ='Modèle de base (CM 2003)'!M3 -> 0
A4: Production | C4: ='Modèle de base (CM 2003)'!C4 -> 0 | D4: ='Modèle de base (CM 2003)'!D4 -> 0 | E4: ='Modèle de base (CM 2003)'!E4 -> 0 | F4: ='Modèle de base (CM 2003)'!F4 -> 0 | G4: ='Modèle de base (CM 2003)'!G4 -> 0 | H4: ='Modèle de base (CM 2003)'!H4 -> 0 | I4: ='Modèle de base (CM 2003)'!I4 -> 0 | J4: ='Modèle de base (CM 2003)'!J4 -> 0 | ... M4: ='Modèle de base (CM 2003)'!M4 -> 0
A5: Quantité Traité | B5: t | C5: ='Modèle de base (CM 2003)'!C5 -> 0 | D5: ='Modèle de base (CM 2003)'!D5 -> 0 | E5: ='Modèle de base (CM 2003)'!E5 -> 0 | F5: ='Modèle de base (CM 2003)'!F5 -> 0 | G5: ='Modèle de base (CM 2003)'!G5 -> 0 | H5: ='Modèle de base (CM 2003)'!H5 -> 0 | I5: ='Modèle de base (CM 2003)'!I5 -> 0 | J5: ='Modèle de base (CM 2003)'!J5 -> 0 | ... M5: ='Modèle de base (CM 2003)'!M5 -> 0
A6: Teneur en or | B6: g/t | C6: ='Modèle de base (CM 2003)'!C6 -> 0 | D6: ='Modèle de base (CM 2003)'!D6 -> 0 | E6: ='Modèle de base (CM 2003)'!E6 -> 0 | F6: ='Modèle de base (CM 2003)'!F6 -> 0 | G6: ='Modèle de base (CM 2003)'!G6 -> 0 | H6: ='Modèle de base (CM 2003)'!H6 -> 0 | I6: ='Modèle de base (CM 2003)'!I6 -> 0 | J6: ='Modèle de base (CM 2003)'!J6 -> 0 | ... M6: ='Modèle de base (CM 2003)'!M6 -> 0
A7: Quantité d'Or Récupéré | B7: oz | C7: ='Modèle de base (CM 2003)'!C7 -> 0 | D7: ='Modèle de base (CM 2003)'!D7 -> 0 | E7: ='Modèle de base (CM 2003)'!E7 -> 191176 | F7: ='Modèle de base (CM 2003)'!F7 -> 215238 | G7: ='Modèle de base (CM 2003)'!G7 -> 189807 | H7: ='Modèle de base (CM 2003)'!H7 -> 168325 | I7: ='Modèle de base (CM 2003)'!I7 -> 210971 | J7: ='Modèle de base (CM 2003)'!J7 -> 167700 | ... M7: ='Modèle de base (CM 2003)'!M7 -> 119370
A8: Cours de l'or | B8: =Q10 -> 1300 | C8: ='Modèle de base (CM 2003)'!C8 -> 0 | D8: ='Modèle de base (CM 2003)'!D8 -> 0 | E8: ='Modèle de base (CM 2003)'!E8 -> 1300 | F8: ='Modèle de base (CM 2003)'!F8 -> 1300 | G8: ='Modèle de base (CM 2003)'!G8 -> 1300 | H8: ='Modèle de base (CM 2003)'!H8 -> 1300 | I8: ='Modèle de base (CM 2003)'!I8 -> 1300 | J8: ='Modèle de base (CM 2003)'!J8 -> 1300 | ... M8: ='Modèle de base (CM 2003)'!M8 -> 1300
A9: Chiffre d'Affaire | B9: $ | C9: =$B$8*C7 -> 0 | D9: =$B$8*D7 -> 0 | E9: =$B$8*E7 -> 248528800 | F9: =$B$8*F7 -> 279809400 | G9: =$B$8*G7 -> 246749100 | H9: =$B$8*H7 -> 218822500 | I9: =$B$8*I7 -> 274262300 | J9: =$B$8*J7 -> 218010000 | ... M9: =$B$8*M7 -> 155181000 | Q9: Données | R9: VAN AV IMPÔT | S9: VAN AP IMPÔT | T9: TEMI | U9: TRI AV | V9: TRI AP
A10: Taux de change | B10: 602.60042 | C10: ='Modèle de base (CM 2003)'!C10 -> 0 | D10: ='Modèle de base (CM 2003)'!D10 -> 0 | E10: ='Modèle de base (CM 2003)'!E10 -> 0 | F10: ='Modèle de base (CM 2003)'!F10 -> 0 | G10: ='Modèle de base (CM 2003)'!G10 -> 0 | H10: ='Modèle de base (CM 2003)'!H10 -> 0 | I10: ='Modèle de base (CM 2003)'!I10 -> 0 | J10: ='Modèle de base (CM 2003)'!J10 -> 0 | ... M10: ='Modèle de base (CM 2003)'!M10 -> 0 | P10: Cours de l'or | Q10: 1300 | R10: =C26 -> 3.5817536e+08 | S10: =C56 -> 1.4052529e+08 | T10: =C57 -> 0.60766343 | U10: =C27 -> 0.27738179 | V10: =C58 -> 0.15060915
A11: Taux d'actualisation | B11: =Q11 -> 0.05 | C11: ='Modèle de base (CM 2003)'!C11 -> 0 | D11: ='Modèle de base (CM 2003)'!D11 -> 0 | E11: ='Modèle de base (CM 2003)'!E11 -> 0 | F11: ='Modèle de base (CM 2003)'!F11 -> 0 | G11: ='Modèle de base (CM 2003)'!G11 -> 0 | H11: ='Modèle de base (CM 2003)'!H11 -> 0 | I11: ='Modèle de base (CM 2003)'!I11 -> 0 | J11: ='Modèle de base (CM 2003)'!J11 -> 0 | ... M11: ='Modèle de base (CM 2003)'!M11 -> 0 | P11: Taux d'actualisation | Q11: 0.05
C12: ='Modèle de base (CM 2003)'!C12 -> 0 | D12: ='Modèle de base (CM 2003)'!D12 -> 0 | E12: ='Modèle de base (CM 2003)'!E12 -> 0 | F12: ='Modèle de base (CM 2003)'!F12 -> 0 | G12: ='Modèle de base (CM 2003)'!G12 -> 0 | H12: ='Modèle de base (CM 2003)'!H12 -> 0 | I12: ='Modèle de base (CM 2003)'!I12 -> 0 | J12: ='Modèle de base (CM 2003)'!J12 -> 0 | ... M12: ='Modèle de base (CM 2003)'!M12 -> 0 | P12: IS | Q12: 0.275
A13: Coûts d'investissement (CAPEX) | C13: ='Modèle de base (CM 2003)'!C13 -> 0 | D13: ='Modèle de base (CM 2003)'!D13 -> 0 | E13: ='Modèle de base (CM 2003)'!E13 -> 0 | F13: ='Modèle de base (CM 2003)'!F13 -> 0 | G13: ='Modèle de base (CM 2003)'!G13 -> 0 | H13: ='Modèle de base (CM 2003)'!H13 -> 0 | I13: ='Modèle de base (CM 2003)'!I13 -> 0 | J13: ='Modèle de base (CM 2003)'!J13 -> 0 | ... M13: ='Modèle de base (CM 2003)'!M13 -> 0 | P13: Taux de redevance propotionelle | Q13: 0.04
A14: Coûts des construction industrielles | B14: $ | C14: ='Modèle de base (CM 2003)'!C14 -> 49760265 | D14: ='Modèle de base (CM 2003)'!D14 -> 116107284 | E14: ='Modèle de base (CM 2003)'!E14 -> 0 | F14: ='Modèle de base (CM 2003)'!F14 -> 0 | G14: ='Modèle de base (CM 2003)'!G14 -> 0 | H14: ='Modèle de base (CM 2003)'!H14 -> 0 | I14: ='Modèle de base (CM 2003)'!I14 -> 0 | J14: ='Modèle de base (CM 2003)'!J14 -> 0 | ... M14: ='Modèle de base (CM 2003)'!M14 -> 0
A15: Coûts des biens d'équipement | C15: ='Modèle de base (CM 2003)'!C15 -> 23685527 | D15: ='Modèle de base (CM 2003)'!D15 -> 125300533 | E15: ='Modèle de base (CM 2003)'!E15 -> 11632917 | F15: ='Modèle de base (CM 2003)'!F15 -> 3722927 | G15: ='Modèle de base (CM 2003)'!G15 -> 18272647 | H15: ='Modèle de base (CM 2003)'!H15 -> 4482500 | I15: ='Modèle de base (CM 2003)'!I15 -> 2137128 | J15: ='Modèle de base (CM 2003)'!J15 -> 1103055 | ... M15: ='Modèle de base (CM 2003)'!M15 -> 542926
A16: Autres depenses | B16: $ | C16: ='Modèle de base (CM 2003)'!C16 -> 0 | D16: ='Modèle de base (CM 2003)'!D16 -> 0 | E16: ='Modèle de base (CM 2003)'!E16 -> 1595000 | F16: ='Modèle de base (CM 2003)'!F16 -> 2708200 | G16: ='Modèle de base (CM 2003)'!G16 -> 249700 | H16: ='Modèle de base (CM 2003)'!H16 -> 2581553 | I16: ='Modèle de base (CM 2003)'!I16 -> 469553 | J16: ='Modèle de base (CM 2003)'!J16 -> 3654542 | ... M16: ='Modèle de base (CM 2003)'!M16 -> 0
A17: Coûts de réhabilitation du site | B17: $ | C17: ='Modèle de base (CM 2003)'!C17 -> 0 | D17: ='Modèle de base (CM 2003)'!D17 -> 0 | E17: ='Modèle de base (CM 2003)'!E17 -> 2830244 | F17: ='Modèle de base (CM 2003)'!F17 -> 3314368 | G17: ='Modèle de base (CM 2003)'!G17 -> 3215137 | H17: ='Modèle de base (CM 2003)'!H17 -> 3842412 | I17: ='Modèle de base (CM 2003)'!I17 -> 4018506 | J17: ='Modèle de base (CM 2003)'!J17 -> 2935298 | ... M17: ='Modèle de base (CM 2003)'!M17 -> 3165512
A18: TOTAL CAPITAL | B18: $ | C18: =SUM(C14:C17) -> 73445792 | D18: =SUM(D14:D17) -> 241407817 | E18: =SUM(E14:E17) -> 16058161 | F18: =SUM(F14:F17) -> 9745495 | G18: =SUM(G14:G17) -> 21737484 | H18: =SUM(H14:H17) -> 10906465 | I18: =SUM(I14:I17) -> 6625187 | J18: =SUM(J14:J17) -> 7692895 | ... M18: =SUM(M14:M17) -> 3708438
C19: ='Modèle de base (CM 2003)'!C19 -> 0 | D19: ='Modèle de base (CM 2003)'!D19 -> 0 | E19: ='Modèle de base (CM 2003)'!E19 -> 0 | F19: ='Modèle de base (CM 2003)'!F19 -> 0 | G19: ='Modèle de base (CM 2003)'!G19 -> 0 | H19: ='Modèle de base (CM 2003)'!H19 -> 0 | I19: ='Modèle de base (CM 2003)'!I19 -> 0 | J19: ='Modèle de base (CM 2003)'!J19 -> 0 | ... M19: ='Modèle de base (CM 2003)'!M19 -> 0
A20: Coûts d'exploitation (Opex)/hors redevance | B20: $ | C20: ='Modèle de base (CM 2003)'!C20 -> 0 | D20: ='Modèle de base (CM 2003)'!D20 -> 0 | E20: ='Modèle de base (CM 2003)'!E20 -> 115668594 | F20: ='Modèle de base (CM 2003)'!F20 -> 128519703 | G20: ='Modèle de base (CM 2003)'!G20 -> 131246978 | H20: ='Modèle de base (CM 2003)'!H20 -> 152348402 | I20: ='Modèle de base (CM 2003)'!I20 -> 157632470 | J20: ='Modèle de base (CM 2003)'!J20 -> 132358509 | ... M20: ='Modèle de base (CM 2003)'!M20 -> 9542514
A21: Coûts d'exploitation moyen (Opex) /hors redevance | B21: $/oz | C21: ='Modèle de base (CM 2003)'!C21 -> 0 | D21: ='Modèle de base (CM 2003)'!D21 -> 0 | E21: ='Modèle de base (CM 2003)'!E21 -> 605.03721 | F21: ='Modèle de base (CM 2003)'!F21 -> 597.10508 | G21: ='Modèle de base (CM 2003)'!G21 -> 691.47596 | H21: ='Modèle de base (CM 2003)'!H21 -> 905.08482 | I21: ='Modèle de base (CM 2003)'!I21 -> 747.17601 | J21: ='Modèle de base (CM 2003)'!J21 -> 789.25766 | ... M21: ='Modèle de base (CM 2003)'!M21 -> 79.940638
C22: ='Modèle de base (CM 2003)'!C22 -> 0 | D22: ='Modèle de base (CM 2003)'!D22 -> 0 | E22: ='Modèle de base (CM 2003)'!E22 -> 0 | F22: ='Modèle de base (CM 2003)'!F22 -> 0 | G22: ='Modèle de base (CM 2003)'!G22 -> 0 | H22: ='Modèle de base (CM 2003)'!H22 -> 0 | I22: ='Modèle de base (CM 2003)'!I22 -> 0 | J22: ='Modèle de base (CM 2003)'!J22 -> 0 | ... M22: ='Modèle de base (CM 2003)'!M22 -> 0
A23: Coût Totaux | C23: =C18+C20 -> 73445792 | D23: =D18+D20 -> 241407817 | E23: =E18+E20 -> 131726755 | F23: =F18+F20 -> 138265198 | G23: =G18+G20 -> 152984462 | H23: =H18+H20 -> 163254867 | I23: =I18+I20 -> 164257657 | J23: =J18+J20 -> 140051404 | ... M23: =M18+M20 -> 13250952
C24: ='Modèle de base (CM 2003)'!C24 -> 0 | D24: ='Modèle de base (CM 2003)'!D24 -> 0 | E24: ='Modèle de base (CM 2003)'!E24 -> 0 | F24: ='Modèle de base (CM 2003)'!F24 -> 0 | G24: ='Modèle de base (CM 2003)'!G24 -> 0 | H24: ='Modèle de base (CM 2003)'!H24 -> 0 | I24: ='Modèle de base (CM 2003)'!I24 -> 0 | J24: ='Modèle de base (CM 2003)'!J24 -> 0 | ... M24: ='Modèle de base (CM 2003)'!M24 -> 0
A25: Cash-flows avant impôts | C25: =C$9-C$23 -> -73445792 | D25: =D$9-D$23 -> -241407817 | E25: =E$9-E$23 -> 116802045 | F25: =F$9-F$23 -> 141544202 | G25: =G$9-G$23 -> 93764638 | H25: =H$9-H$23 -> 55567633 | I25: =I$9-I$23 -> 110004643 | J25: =J$9-J$23 -> 77958596 | ... M25: =M$9-M$23 -> 141930048
A26: VAN avant impôts | C26: =NPV(B11,C25:M25) -> 3.5817536e+08 | D26: ='Modèle de base (CM 2003)'!D26 -> 0 | E26: ='Modèle de base (CM 2003)'!E26 -> 0 | F26: ='Modèle de base (CM 2003)'!F26 -> 0 | G26: ='Modèle de base (CM 2003)'!G26 -> 0 | H26: ='Modèle de base (CM 2003)'!H26 -> 0 | I26: ='Modèle de base (CM 2003)'!I26 -> 0 | J26: ='Modèle de base (CM 2003)'!J26 -> 0 | K26: ='Modèle de base (CM 2003)'!K26 -> 0 | ... M26: ='Modèle de base (CM 2003)'!M26 -> 0
A27: TRI avant impôts | C27: =IRR(C25:M25) -> 0.27738179
C28: ='Modèle de base (CM 2003)'!C28 -> 0
A29: Droits fixes | B29: 10000000 | C29: ='Données fiscales'!C89/'Code Minier 2015'!B10 -> 16594.744
C30: ='Modèle de base (CM 2003)'!C30 -> 0
C31: ='Modèle de base (CM 2003)'!C31 -> 0
A32: Superficie de la mine | C32: ='Modèle de base (CM 2003)'!C32 -> 23.2 | D32: ='Modèle de base (CM 2003)'!D32 -> 23.2 | E32: ='Modèle de base (CM 2003)'!E32 -> 23.2 | F32: ='Modèle de base (CM 2003)'!F32 -> 23.2 | G32: ='Modèle de base (CM 2003)'!G32 -> 23.2 | H32: ='Modèle de base (CM 2003)'!H32 -> 23.2 | I32: ='Modèle de base (CM 2003)'!I32 -> 23.2 | J32: ='Modèle de base (CM 2003)'!J32 -> 23.2 | ... M32: ='Modèle de base (CM 2003)'!M32 -> 23.2
A33: Redevance superficière | C33: ='Modèle de base (CM 2003)'!C33 -> 352936.77 | D33: ='Modèle de base (CM 2003)'!D33 -> 352936.77 | E33: ='Modèle de base (CM 2003)'!E33 -> 352936.77 | F33: ='Modèle de base (CM 2003)'!F33 -> 352936.77 | G33: ='Modèle de base (CM 2003)'!G33 -> 352936.77 | H33: ='Modèle de base (CM 2003)'!H33 -> 470582.36 | I33: ='Modèle de base (CM 2003)'!I33 -> 470582.36 | J33: ='Modèle de base (CM 2003)'!J33 -> 470582.36 | ... M33: ='Modèle de base (CM 2003)'!M33 -> 705873.55
C34: ='Modèle de base (CM 2003)'!C34 -> 0 | D34: ='Modèle de base (CM 2003)'!D34 -> 0 | E34: ='Modèle de base (CM 2003)'!E34 -> 0 | F34: ='Modèle de base (CM 2003)'!F34 -> 0 | G34: ='Modèle de base (CM 2003)'!G34 -> 0 | H34: ='Modèle de base (CM 2003)'!H34 -> 0 | I34: ='Modèle de base (CM 2003)'!I34 -> 0 | J34: ='Modèle de base (CM 2003)'!J34 -> 0 | ... M34: ='Modèle de base (CM 2003)'!M34 -> 0
A35: Redevance proportionnelle | C35: ='Modèle de base (CM 2003)'!C35 -> 0 | D35: ='Modèle de base (CM 2003)'!D35 -> 0 | E35: ='Modèle de base (CM 2003)'!E35 -> 0 | F35: ='Modèle de base (CM 2003)'!F35 -> 0 | G35: ='Modèle de base (CM 2003)'!G35 -> 0 | H35: ='Modèle de base (CM 2003)'!H35 -> 0 | I35: ='Modèle de base (CM 2003)'!I35 -> 0 | J35: ='Modèle de base (CM 2003)'!J35 -> 0 | ... M35: ='Modèle de base (CM 2003)'!M35 -> 0
A36: taux de la redevance | B36: =Q13 -> 0.04 | C36: ='Modèle de base (CM 2003)'!C36 -> 0 | D36: ='Modèle de base (CM 2003)'!D36 -> 0 | E36: ='Modèle de base (CM 2003)'!E36 -> 0.04 | F36: ='Modèle de base (CM 2003)'!F36 -> 0.04 | G36: ='Modèle de base (CM 2003)'!G36 -> 0.04 | H36: ='Modèle de base (CM 2003)'!H36 -> 0.04 | I36: ='Modèle de base (CM 2003)'!I36 -> 0.04 | J36: ='Modèle de base (CM 2003)'!J36 -> 0.04 | ... M36: ='Modèle de base (CM 2003)'!M36 -> 0.04
A37: Montant de la redevance | C37: =$B$36*C9 -> 0 | D37: =$B$36*D9 -> 0 | E37: =$B$36*E9 -> 9941152 | F37: =$B$36*F9 -> 11192376 | G37: =$B$36*G9 -> 9869964 | H37: =$B$36*H9 -> 8752900 | I37: =$B$36*I9 -> 10970492 | J37: =$B$36*J9 -> 8720400 | ... M37: =$B$36*M9 -> 6207240
C38: ='Modèle de base (CM 2003)'!C38 -> 0 | D38: ='Modèle de base (CM 2003)'!D38 -> 0 | E38: ='Modèle de base (CM 2003)'!E38 -> 0 | F38: ='Modèle de base (CM 2003)'!F38 -> 0 | G38: ='Modèle de base (CM 2003)'!G38 -> 0 | H38: ='Modèle de base (CM 2003)'!H38 -> 0 | I38: ='Modèle de base (CM 2003)'!I38 -> 0 | J38: ='Modèle de base (CM 2003)'!J38 -> 0 | ... M38: ='Modèle de base (CM 2003)'!M38 -> 0
A39: Charges d'amortissement | C39: ='Modèle de base (CM 2003)'!C39 -> 14450237 | D39: ='Modèle de base (CM 2003)'!D39 -> 72391495 | E39: ='Modèle de base (CM 2003)'!E39 -> 54722766 | F39: ='Modèle de base (CM 2003)'!F39 -> 41469139 | G39: ='Modèle de base (CM 2003)'!G39 -> 42554951 | H39: ='Modèle de base (CM 2003)'!H39 -> 38090104 | I39: ='Modèle de base (CM 2003)'!I39 -> 22807098 | J39: ='Modèle de base (CM 2003)'!J39 -> 20561890 | ... M39: ='Modèle de base (CM 2003)'!M39 -> 15427244
A40: Developpement local | C40: =C9*'Données fiscales'!C95 -> 0 | D40: =D9*'Données fiscales'!D95 -> 0 | E40: =E9*'Données fiscales'!E95 -> 2485288 | F40: =F9*'Données fiscales'!F95 -> 2798094 | G40: =G9*'Données fiscales'!G95 -> 2467491 | H40: =H9*'Données fiscales'!H95 -> 2188225 | I40: =I9*'Données fiscales'!I95 -> 2742623 | J40: =J9*'Données fiscales'!J95 -> 2180100 | ... M40: =M9*'Données fiscales'!M95 -> 1551810
...

Sheet Code général des impôts 2017
A1: Projet aurifère_De Houndé | B1: Unités | C1: ='Modèle de base (CM 2003)'!C1 -> 2011 | D1: ='Modèle de base (CM 2003)'!D1 -> 2012 | E1: ='Modèle de base (CM 2003)'!E1 -> 2013 | F1: ='Modèle de base (CM 2003)'!F1 -> 2014 | G1: ='Modèle de base (CM 2003)'!G1 -> 2015 | H1: ='Modèle de base (CM 2003)'!H1 -> 2016 | I1: ='Modèle de base (CM 2003)'!I1 -> 2017 | J1: ='Modèle de base (CM 2003)'!J1 -> 2018 | ... M1: ='Modèle de base (CM 2003)'!M1 -> 2021
C2: ='Modèle de base (CM 2003)'!C2 -> 0 | D2: ='Modèle de base (CM 2003)'!D2 -> 0 | E2: ='Modèle de base (CM 2003)'!E2 -> 0 | F2: ='Modèle de base (CM 2003)'!F2 -> 0 | G2: ='Modèle de base (CM 2003)'!G2 -> 0 | H2: ='Modèle de base (CM 2003)'!H2 -> 0 | I2: ='Modèle de base (CM 2003)'!I2 -> 0 | J2: ='Modèle de base (CM 2003)'!J2 -> 0 | ... M2: ='Modèle de base (CM 2003)'!M2 -> 0
C3: ='Modèle de base (CM 2003)'!C3 -> 0 | D3: ='Modèle de base (CM 2003)'!D3 -> 0 | E3: ='Modèle de base (CM 2003)'!E3 -> 0 | F3: ='Modèle de base (CM 2003)'!F3 -> 0 | G3: ='Modèle de base (CM 2003)'!G3 -> 0 | H3: ='Modèle de base (CM 2003)'!H3 -> 0 | I3: ='Modèle de base (CM 2003)'!I3 -> 0 | J3: ='Modèle de base (CM 2003)'!J3 -> 0 | ... M3: ='Modèle de base (CM 2003)'!M3 -> 0
A4: Production | C4: ='Modèle de base (CM 2003)'!C4 -> 0 | D4: ='Modèle de base (CM 2003)'!D4 -> 0 | E4: ='Modèle de base (CM 2003)'!E4 -> 0 | F4: ='Modèle de base (CM 2003)'!F4 -> 0 | G4: ='Modèle de base (CM 2003)'!G4 -> 0 | H4: ='Modèle de base (CM 2003)'!H4 -> 0 | I4: ='Modèle de base (CM 2003)'!I4 -> 0 | J4: ='Modèle de base (CM 2003)'!J4 -> 0 | ... M4: ='Modèle de base (CM 2003)'!M4 -> 0 | Q4: Données | R4: VAN AV IMPÔT | S4: VAN AP IMPÔT | T4: TEMI | U4: TRI AV | V4: TRI AP
A5: Quantité Traité | B5: t | C5: ='Modèle de base (CM 2003)'!C5 -> 0 | D5: ='Modèle de base (CM 2003)'!D5 -> 0 | E5: ='Modèle de base (CM 2003)'!E5 -> 0 | F5: ='Modèle de base (CM 2003)'!F5 -> 0 | G5: ='Modèle de base (CM 2003)'!G5 -> 0 | H5: ='Modèle de base (CM 2003)'!H5 -> 0 | I5: ='Modèle de base (CM 2003)'!I5 -> 0 | J5: ='Modèle de base (CM 2003)'!J5 -> 0 | ... M5: ='Modèle de base (CM 2003)'!M5 -> 0 | P5: Cours de l'or | Q5: 1300 | R5: =C26 -> 3.5817536e+08 | S5: =C56 -> 99393777 | T5: =C57 -> 0.72249968 | U5: =C27 -> 0.27738179 | V5: =C58 -> 0.12307964
A6: Teneur en or | B6: g/t | C6: ='Modèle de base (CM 2003)'!C6 -> 0 | D6: ='Modèle de base (CM 2003)'!D6 -> 0 | E6: ='Modèle de base (CM 2003)'!E6 -> 0 | F6: ='Modèle de base (CM 2003)'!F6 -> 0 | G6: ='Modèle de base (CM 2003)'!G6 -> 0 | H6: ='Modèle de base (CM 2003)'!H6 -> 0 | I6: ='Modèle de base (CM 2003)'!I6 -> 0 | J6: ='Modèle de base (CM 2003)'!J6 -> 0 | ... M6: ='Modèle de base (CM 2003)'!M6 -> 0 | P6: Taux d'actualisation | Q6: 0.05
A7: Quantité d'Or Récupéré | B7: oz | C7: ='Modèle de base (CM 2003)'!C7 -> 0 | D7: ='Modèle de base (CM 2003)'!D7 -> 0 | E7: ='Modèle de base (CM 2003)'!E7 -> 191176 | F7: ='Modèle de base (CM 2003)'!F7 -> 215238 | G7: ='Modèle de base (CM 2003)'!G7 -> 189807 | H7: ='Modèle de base (CM 2003)'!H7 -> 168325 | I7: ='Modèle de base (CM 2003)'!I7 -> 210971 | J7: ='Modèle de base (CM 2003)'!J7 -> 167700 | ... M7: ='Modèle de base (CM 2003)'!M7 -> 119370 | P7: IS | Q7: 0.275
A8: Cours de l'or | B8: =Q5 -> 1300 | C8: ='Modèle de base (CM 2003)'!C8 -> 0 | D8: ='Modèle de base (CM 2003)'!D8 -> 0 | E8: ='Modèle de base (CM 2003)'!E8 -> 1300 | F8: ='Modèle de base (CM 2003)'!F8 -> 1300 | G8: ='Modèle de base (CM 2003)'!G8 -> 1300 | H8: ='Modèle de base (CM 2003)'!H8 -> 1300 | I8: ='Modèle de base (CM 2003)'!I8 -> 1300 | J8: ='Modèle de base (CM 2003)'!J8 -> 1300 | ... M8: ='Modèle de base (CM 2003)'!M8 -> 1300 | P8: Taux de redevance propotionelle | Q8: 0.04
A9: Chiffre d'Affaire | B9: $ | C9: =$B$8*C7 -> 0 | D9: =$B$8*D7 -> 0 | E9: =$B$8*E7 -> 248528800 | F9: =$B$8*F7 -> 279809400 | G9: =$B$8*G7 -> 246749100 | H9: =$B$8*H7 -> 218822500 | I9: =$B$8*I7 -> 274262300 | J9: =$B$8*J7 -> 218010000 | ... M9: =$B$8*M7 -> 155181000
A10: Taux de change | B10: 0.00177 | C10: ='Modèle de base (CM 2003)'!C10 -> 0 | D10: ='Modèle de base (CM 2003)'!D10 -> 0 | E10: ='Modèle de base (CM 2003)'!E10 -> 0 | F10: ='Modèle de base (CM 2003)'!F10 -> 0 | G10: ='Modèle de base (CM 2003)'!G10 -> 0 | H10: ='Modèle de base (CM 2003)'!H10 -> 0 | I10: ='Modèle de base (CM 2003)'!I10 -> 0 | J10: ='Modèle de base (CM 2003)'!J10 -> 0 | ... M10: ='Modèle de base (CM 2003)'!M10 -> 0
A11: Taux d'actualisation | B11: =Q6 -> 0.05 | C11: ='Modèle de base (CM 2003)'!C11 -> 0 | D11: ='Modèle de base (CM 2003)'!D11 -> 0 | E11: ='Modèle de base (CM 2003)'!E11 -> 0 | F11: ='Modèle de base (CM 2003)'!F11 -> 0 | G11: ='Modèle de base (CM 2003)'!G11 -> 0 | H11: ='Modèle de base (CM 2003)'!H11 -> 0 | I11: ='Modèle de base (CM 2003)'!I11 -> 0 | J11: ='Modèle de base (CM 2003)'!J11 -> 0 | ... M11: ='Modèle de base (CM 2003)'!M11 -> 0
C12: ='Modèle de base (CM 2003)'!C12 -> 0 | D12: ='Modèle de base (CM 2003)'!D12 -> 0 | E12: ='Modèle de base (CM 2003)'!E12 -> 0 | F12: ='Modèle de base (CM 2003)'!F12 -> 0 | G12: ='Modèle de base (CM 2003)'!G12 -> 0 | H12: ='Modèle de base (CM 2003)'!H12 -> 0 | I12: ='Modèle de base (CM 2003)'!I12 -> 0 | J12: ='Modèle de base (CM 2003)'!J12 -> 0 | ... M12: ='Modèle de base (CM 2003)'!M12 -> 0
A13: Coûts d'investissement (CAPEX) | C13: ='Modèle de base (CM 2003)'!C13 -> 0 | D13: ='Modèle de base (CM 2003)'!D13 -> 0 | E13: ='Modèle de base (CM 2003)'!E13 -> 0 | F13: ='Modèle de base (CM 2003)'!F13 -> 0 | G13: ='Modèle de base (CM 2003)'!G13 -> 0 | H13: ='Modèle de base (CM 2003)'!H13 -> 0 | I13: ='Modèle de base (CM 2003)'!I13 -> 0 | J13: ='Modèle de base (CM 2003)'!J13 -> 0 | ... M13: ='Modèle de base (CM 2003)'!M13 -> 0
A14: Coûts des construction industrielles | B14: $ | C14: ='Modèle de base (CM 2003)'!C14 -> 49760265 | D14: ='Modèle de base (CM 2003)'!D14 -> 116107284 | E14: ='Modèle de base (CM 2003)'!E14 -> 0 | F14: ='Modèle de base (CM 2003)'!F14 -> 0 | G14: ='Modèle de base (CM 2003)'!G14 -> 0 | H14: ='Modèle de base (CM 2003)'!H14 -> 0 | I14: ='Modèle de base (CM 2003)'!I14 -> 0 | J14: ='Modèle de base (CM 2003)'!J14 -> 0 | ... M14: ='Modèle de base (CM 2003)'!M14 -> 0
A15: Coûts des biens d'équipement | C15: ='Modèle de base (CM 2003)'!C15 -> 23685527 | D15: ='Modèle de base (CM 2003)'!D15 -> 125300533 | E15: ='Modèle de base (CM 2003)'!E15 -> 11632917 | F15: ='Modèle de base (CM 2003)'!F15 -> 3722927 | G15: ='Modèle de base (CM 2003)'!G15 -> 18272647 | H15: ='Modèle de base (CM 2003)'!H15 -> 4482500 | I15: ='Modèle de base (CM 2003)'!I15 -> 2137128 | J15: ='Modèle de base (CM 2003)'!J15 -> 1103055 | ... M15: ='Modèle de base (CM 2003)'!M15 -> 542926
A16: Autres depenses | B16: $ | C16: ='Modèle de base (CM 2003)'!C16 -> 0 | D16: ='Modèle de base (CM 2003)'!D16 -> 0 | E16: ='Modèle de base (CM 2003)'!E16 -> 1595000 | F16: ='Modèle de base (CM 2003)'!F16 -> 2708200 | G16: ='Modèle de base (CM 2003)'!G16 -> 249700 | H16: ='Modèle de base (CM 2003)'!H16 -> 2581553 | I16: ='Modèle de base (CM 2003)'!I16 -> 469553 | J16: ='Modèle de base (CM 2003)'!J16 -> 3654542 | ... M16: ='Modèle de base (CM 2003)'!M16 -> 0
A17: Coûts de réhabilitation du site | B17: $ | C17: ='Modèle de base (CM 2003)'!C17 -> 0 | D17: ='Modèle de base (CM 2003)'!D17 -> 0 | E17: ='Modèle de base (CM 2003)'!E17 -> 2830244 | F17: ='Modèle de base (CM 2003)'!F17 -> 3314368 | G17: ='Modèle de base (CM 2003)'!G17 -> 3215137 | H17: ='Modèle de base (CM 2003)'!H17 -> 3842412 | I17: ='Modèle de base (CM 2003)'!I17 -> 4018506 | J17: ='Modèle de base (CM 2003)'!J17 -> 2935298 | ... M17: ='Modèle de base (CM 2003)'!M17 -> 3165512
A18: TOTAL CAPITAL | B18: $ | C18: ='Modèle de base (CM 2003)'!C18 -> 73445792 | D18: ='Modèle de base (CM 2003)'!D18 -> 241407817 | E18: ='Modèle de base (CM 2003)'!E18 -> 16058161 | F18: ='Modèle de base (CM 2003)'!F18 -> 9745495 | G18: ='Modèle de base (CM 2003)'!G18 -> 21737484 | H18: ='Modèle de base (CM 2003)'!H18 -> 10906465 | I18: ='Modèle de base (CM 2003)'!I18 -> 6625187 | J18: ='Modèle de base (CM 2003)'!J18 -> 7692895 | ... M18: ='Modèle de base (CM 2003)'!M18 -> 3708438
C19: ='Modèle de base (CM 2003)'!C19 -> 0 | D19: ='Modèle de base (CM 2003)'!D19 -> 0 | E19: ='Modèle de base (CM 2003)'!E19 -> 0 | F19: ='Modèle de base (CM 2003)'!F19 -> 0 | G19: ='Modèle de base (CM 2003)'!G19 -> 0 | H19: ='Modèle de base (CM 2003)'!H19 -> 0 | I19: ='Modèle de base (CM 2003)'!I19 -> 0 | J19: ='Modèle de base (CM 2003)'!J19 -> 0 | ... M19: ='Modèle de base (CM 2003)'!M19 -> 0
A20: Coûts d'exploitation (Opex)/hors redevance | B20: $ | C20: ='Modèle de base (CM 2003)'!C20 -> 0 | D20: ='Modèle de base (CM 2003)'!D20 -> 0 | E20: ='Modèle de base (CM 2003)'!E20 -> 115668594 | F20: ='Modèle de base (CM 2003)'!F20 -> 128519703 | G20: ='Modèle de base (CM 2003)'!G20 -> 131246978 | H20: ='Modèle de base (CM 2003)'!H20 -> 152348402 | I20: ='Modèle de base (CM 2003)'!I20 -> 157632470 | J20: ='Modèle de base (CM 2003)'!J20 -> 132358509 | ... M20: ='Modèle de base (CM 2003)'!M20 -> 9542514
A21: Coûts d'exploitation moyen (Opex) /hors redevance | B21: $/oz | C21: ='Modèle de base (CM 2003)'!C21 -> 0 | D21: ='Modèle de base (CM 2003)'!D21 -> 0 | E21: ='Modèle de base (CM 2003)'!E21 -> 605.03721 | F21: ='Modèle de base (CM 2003)'!F21 -> 597.10508 | G21: ='Modèle de base (CM 2003)'!G21 -> 691.47596 | H21: ='Modèle de base (CM 2003)'!H21 -> 905.08482 | I21: ='Modèle de base (CM 2003)'!I21 -> 747.17601 | J21: ='Modèle de base (CM 2003)'!J21 -> 789.25766 | ... M21: ='Modèle de base (CM 2003)'!M21 -> 79.940638
C22: ='Modèle de base (CM 2003)'!C22 -> 0 | D22: ='Modèle de base (CM 2003)'!D22 -> 0 | E22: ='Modèle de base (CM 2003)'!E22 -> 0 | F22: ='Modèle de base (CM 2003)'!F22 -> 0 | G22: ='Modèle de base (CM 2003)'!G22 -> 0 | H22: ='Modèle de base (CM 2003)'!H22 -> 0 | I22: ='Modèle de base (CM 2003)'!I22 -> 0 | J22: ='Modèle de base (CM 2003)'!J22 -> 0 | ... M22: ='Modèle de base (CM 2003)'!M22 -> 0
A23: Coût Totaux | C23: =C$18+C$20 -> 73445792 | D23: =D$18+D$20 -> 241407817 | E23: =E$18+E$20 -> 131726755 | F23: =F$18+F$20 -> 138265198 | G23: =G$18+G$20 -> 152984462 | H23: =H$18+H$20 -> 163254867 | I23: =I$18+I$20 -> 164257657 | J23: =J$18+J$20 -> 140051404 | ... M23: =M$18+M$20 -> 13250952
C24: ='Modèle de base (CM 2003)'!C24 -> 0 | D24: ='Modèle de base (CM 2003)'!D24 -> 0 | E24: ='Modèle de base (CM 2003)'!E24 -> 0 | F24: ='Modèle de base (CM 2003)'!F24 -> 0 | G24: ='Modèle de base (CM 2003)'!G24 -> 0 | H24: ='Modèle de base (CM 2003)'!H24 -> 0 | I24: ='Modèle de base (CM 2003)'!I24 -> 0 | J24: ='Modèle de base (CM 2003)'!J24 -> 0 | ... M24: ='Modèle de base (CM 2003)'!M24 -> 0
A25: Cash-flows avant impôts | C25: =C$9-C$23 -> -73445792 | D25: =D$9-D$23 -> -241407817 | E25: =E$9-E$23 -> 116802045 | F25: =F$9-F$23 -> 141544202 | G25: =G$9-G$23 -> 93764638 | H25: =H$9-H$23 -> 55567633 | I25: =I$9-I$23 -> 110004643 | J25: =J$9-J$23 -> 77958596 | ... M25: =M$9-M$23 -> 141930048
A26: VAN avant impôts | C26: =NPV($B$11,C25:M25) -> 3.5817536e+08 | D26: ='Modèle de base (CM 2003)'!D26 -> 0 | E26: ='Modèle de base (CM 2003)'!E26 -> 0 | F26: ='Modèle de base (CM 2003)'!F26 -> 0 | G26: ='Modèle de base (CM 2003)'!G26 -> 0 | H26: ='Modèle de base (CM 2003)'!H26 -> 0 | I26: ='Modèle de base (CM 2003)'!I26 -> 0 | J26: ='Modèle de base (CM 2003)'!J26 -> 0 | K26: ='Modèle de base (CM 2003)'!K26 -> 0 | ... M26: ='Modèle de base (CM 2003)'!M26 -> 0
A27: TRI avant impôts | C27: =IRR(C25:M25) -> 0.27738179 | D27: ='Modèle de base (CM 2003)'!D27 -> 0 | E27: ='Modèle de base (CM 2003)'!E27 -> -0.3913088 | F27: ='Modèle de base (CM 2003)'!F27 -> 0.11243079 | G27: ='Modèle de base (CM 2003)'!G27 -> 0.2768997 | H27: ='Modèle de base (CM 2003)'!H27 -> 0.3407976 | I27: ='Modèle de base (CM 2003)'!I27 -> 0.40012659 | J27: ='Modèle de base (CM 2003)'!J27 -> 0.42540794 | K27: ='Modèle de base (CM 2003)'!K27 -> 0.43824983 | ... M27: ='Modèle de base (CM 2003)'!M27 -> 0.45818507
C28: ='Modèle de base (CM 2003)'!C28 -> 0 | D28: ='Modèle de base (CM 2003)'!D28 -> 0 | E28: ='Modèle de base (CM 2003)'!E28 -> 0 | F28: ='Modèle de base (CM 2003)'!F28 -> 0 | G28: ='Modèle de base (CM 2003)'!G28 -> 0 | H28: ='Modèle de base (CM 2003)'!H28 -> 0 | I28: ='Modèle de base (CM 2003)'!I28 -> 0 | J28: ='Modèle de base (CM 2003)'!J28 -> 0 | ... M28: ='Modèle de base (CM 2003)'!M28 -> 0
A29: Droits fixes | C29: =B10*'Données fiscales'!C110 -> 9735 | D29: ='Modèle de base (CM 2003)'!D29 -> 0 | E29: ='Modèle de base (CM 2003)'!E29 -> 0 | F29: ='Modèle de base (CM 2003)'!F29 -> 0 | G29: ='Modèle de base (CM 2003)'!G29 -> 0 | H29: ='Modèle de base (CM 2003)'!H29 -> 0 | I29: ='Modèle de base (CM 2003)'!I29 -> 0 | J29: ='Modèle de base (CM 2003)'!J29 -> 0 | K29: ='Modèle de base (CM 2003)'!K29 -> 0 | ... M29: ='Modèle de base (CM 2003)'!M29 -> 0
C30: ='Modèle de base (CM 2003)'!C30 -> 0 | D30: ='Modèle de base (CM 2003)'!D30 -> 0 | E30: ='Modèle de base (CM 2003)'!E30 -> 0 | F30: ='Modèle de base (CM 2003)'!F30 -> 0 | G30: ='Modèle de base (CM 2003)'!G30 -> 0 | H30: ='Modèle de base (CM 2003)'!H30 -> 0 | I30: ='Modèle de base (CM 2003)'!I30 -> 0 | J30: ='Modèle de base (CM 2003)'!J30 -> 0 | ... M30: ='Modèle de base (CM 2003)'!M30 -> 0
C31: ='Modèle de base (CM 2003)'!C31 -> 0 | D31: ='Modèle de base (CM 2003)'!D31 -> 0 | E31: ='Modèle de base (CM 2003)'!E31 -> 0 | F31: ='Modèle de base (CM 2003)'!F31 -> 0 | G31: ='Modèle de base (CM 2003)'!G31 -> 0 | H31: ='Modèle de base (CM 2003)'!H31 -> 0 | I31: ='Modèle de base (CM 2003)'!I31 -> 0 | J31: ='Modèle de base (CM 2003)'!J31 -> 0 | ... M31: ='Modèle de base (CM 2003)'!M31 -> 0
A32: Superficie de la mine | C32: ='Modèle de base (CM 2003)'!C32 -> 23.2 | D32: ='Modèle de base (CM 2003)'!D32 -> 23.2 | E32: ='Modèle de base (CM 2003)'!E32 -> 23.2 | F32: ='Modèle de base (CM 2003)'!F32 -> 23.2 | G32: ='Modèle de base (CM 2003)'!G32 -> 23.2 | H32: ='Modèle de base (CM 2003)'!H32 -> 23.2 | I32: ='Modèle de base (CM 2003)'!I32 -> 23.2 | J32: ='Modèle de base (CM 2003)'!J32 -> 23.2 | ... M32: ='Modèle de base (CM 2003)'!M32 -> 23.2
A33: Redevance superficière | C33: =$B$10*C32*'Données fiscales'!C90 -> 25665 | D33: =$B$10*D32*'Données fiscales'!D90 -> 307980 | E33: =$B$10*E32*'Données fiscales'!E90 -> 307980 | F33: =$B$10*F32*'Données fiscales'!F90 -> 307980 | G33: =$B$10*G32*'Données fiscales'!G90 -> 307980 | H33: =$B$10*H32*'Données fiscales'!H90 -> 410640 | I33: =$B$10*I32*'Données fiscales'!I90 -> 410640 | J33: =$B$10*J32*'Données fiscales'!J90 -> 410640 | ... M33: =$B$10*M32*'Données fiscales'!M90 -> 615960
C34: ='Modèle de base (CM 2003)'!C34 -> 0 | D34: ='Modèle de base (CM 2003)'!D34 -> 0 | E34: ='Modèle de base (CM 2003)'!E34 -> 0 | F34: ='Modèle de base (CM 2003)'!F34 -> 0 | G34: ='Modèle de base (CM 2003)'!G34 -> 0 | H34: ='Modèle de base (CM 2003)'!H34 -> 0 | I34: ='Modèle de base (CM 2003)'!I34 -> 0 | J34: ='Modèle de base (CM 2003)'!J34 -> 0 | ... M34: ='Modèle de base (CM 2003)'!M34 -> 0
A35: Redevance proportionnelle | C35: ='Modèle de base (CM 2003)'!C35 -> 0 | D35: ='Modèle de base (CM 2003)'!D35 -> 0 | E35: ='Modèle de base (CM 2003)'!E35 -> 0 | F35: ='Modèle de base (CM 2003)'!F35 -> 0 | G35: ='Modèle de base (CM 2003)'!G35 -> 0 | H35: ='Modèle de base (CM 2003)'!H35 -> 0 | I35: ='Modèle de base (CM 2003)'!I35 -> 0 | J35: ='Modèle de base (CM 2003)'!J35 -> 0 | ... M35: ='Modèle de base (CM 2003)'!M35 -> 0
A36: taux de la redevance | B36: =Q8 -> 0.04 | C36: ='Modèle de base (CM 2003)'!C36 -> 0 | D36: ='Modèle de base (CM 2003)'!D36 -> 0 | E36: ='Modèle de base (CM 2003)'!E36 -> 0.04 | F36: ='Modèle de base (CM 2003)'!F36 -> 0.04 | G36: ='Modèle de base (CM 2003)'!G36 -> 0.04 | H36: ='Modèle de base (CM 2003)'!H36 -> 0.04 | I36: ='Modèle de base (CM 2003)'!I36 -> 0.04 | J36: ='Modèle de base (CM 2003)'!J36 -> 0.04 | ... M36: ='Modèle de base (CM 2003)'!M36 -> 0.04
A37: Montant de la redevance | C37: =$B$36*C9 -> 0 | D37: =$B$36*D9 -> 0 | E37: =$B$36*E9 -> 9941152 | F37: =$B$36*F9 -> 11192376 | G37: =$B$36*G9 -> 9869964 | H37: =$B$36*H9 -> 8752900 | I37: =$B$36*I9 -> 10970492 | J37: =$B$36*J9 -> 8720400 | ... M37: =$B$36*M9 -> 6207240
C38: ='Modèle de base (CM 2003)'!C38 -> 0 | D38: ='Modèle de base (CM 2003)'!D38 -> 0 | E38: ='Modèle de base (CM 2003)'!E38 -> 0 | F38: ='Modèle de base (CM 2003)'!F38 -> 0 | G38: ='Modèle de base (CM 2003)'!G38 -> 0 | H38: ='Modèle de base (CM 2003)'!H38 -> 0 | I38: ='Modèle de base (CM 2003)'!I38 -> 0 | J38: ='Modèle de base (CM 2003)'!J38 -> 0 | ... M38: ='Modèle de base (CM 2003)'!M38 -> 0
A39: Charges d'amortissement | C39: ='Modèle de base (CM 2003)'!C39 -> 14450237 | D39: ='Modèle de base (CM 2003)'!D39 -> 72391495 | E39: ='Modèle de base (CM 2003)'!E39 -> 54722766 | F39: ='Modèle de base (CM 2003)'!F39 -> 41469139 | G39: ='Modèle de base (CM 2003)'!G39 -> 42554951 | H39: ='Modèle de base (CM 2003)'!H39 -> 38090104 | I39: ='Modèle de base (CM 2003)'!I39 -> 22807098 | J39: ='Modèle de base (CM 2003)'!J39 -> 20561890 | ... M39: ='Modèle de base (CM 2003)'!M39 -> 15427244
A40: ='Code Minier 2015'!A40 -> Developpement local | B40: ='Code Minier 2015'!B40 -> 0 | C40: ='Code Minier 2015'!C40 -> 0 | D40: ='Code Minier 2015'!D40 -> 0 | E40: ='Code Minier 2015'!E40 -> 2485288 | F40: ='Code Minier 2015'!F40 -> 2798094 | G40: ='Code Minier 2015'!G40 -> 2467491 | H40: ='Code Minier 2015'!H40 -> 2188225 | ... M40: ='Code Minier 2015'!M40 -> 1551810
...

Sheet BURKINA code minier 2003
A1: Projet aurifère_De Houndé | B1: Unités | C1: ='Modèle de base (CM 2003)'!C1 -> 2011 | D1: ='Modèle de base (CM 2003)'!D1 -> 2012 | E1: ='Modèle de base (CM 2003)'!E1 -> 2013 | F1: ='Modèle de base (CM 2003)'!F1 -> 2014 | G1: ='Modèle de base (CM 2003)'!G1 -> 2015 | H1: ='Modèle de base (CM 2003)'!H1 -> 2016 | I1: ='Modèle de base (CM 2003)'!I1 -> 2017 | J1: ='Modèle de base (CM 2003)'!J1 -> 2018 | ... M1: ='Modèle de base (CM 2003)'!M1 -> 2021
C2: ='Modèle de base (CM 2003)'!C2 -> 0 | D2: ='Modèle de base (CM 2003)'!D2 -> 0 | E2: ='Modèle de base (CM 2003)'!E2 -> 0 | F2: ='Modèle de base (CM 2003)'!F2 -> 0 | G2: ='Modèle de base (CM 2003)'!G2 -> 0 | H2: ='Modèle de base (CM 2003)'!H2 -> 0 | I2: ='Modèle de base (CM 2003)'!I2 -> 0 | J2: ='Modèle de base (CM 2003)'!J2 -> 0 | ... M2: ='Modèle de base (CM 2003)'!M2 -> 0
C3: ='Modèle de base (CM 2003)'!C3 -> 0 | D3: ='Modèle de base (CM 2003)'!D3 -> 0 | E3: ='Modèle de base (CM 2003)'!E3 -> 0 | F3: ='Modèle de base (CM 2003)'!F3 -> 0 | G3: ='Modèle de base (CM 2003)'!G3 -> 0 | H3: ='Modèle de base (CM 2003)'!H3 -> 0 | I3: ='Modèle de base (CM 2003)'!I3 -> 0 | J3: ='Modèle de base (CM 2003)'!J3 -> 0 | ... M3: ='Modèle de base (CM 2003)'!M3 -> 0
A4: Production | C4: ='Modèle de base (CM 2003)'!C4 -> 0 | D4: ='Modèle de base (CM 2003)'!D4 -> 0 | E4: ='Modèle de base (CM 2003)'!E4 -> 0 | F4: ='Modèle de base (CM 2003)'!F4 -> 0 | G4: ='Modèle de base (CM 2003)'!G4 -> 0 | H4: ='Modèle de base (CM 2003)'!H4 -> 0 | I4: ='Modèle de base (CM 2003)'!I4 -> 0 | J4: ='Modèle de base (CM 2003)'!J4 -> 0 | ... M4: ='Modèle de base (CM 2003)'!M4 -> 0
A5: Quantité Traité | B5: t | C5: ='Modèle de base (CM 2003)'!C5 -> 0 | D5: ='Modèle de base (CM 2003)'!D5 -> 0 | E5: ='Modèle de base (CM 2003)'!E5 -> 0 | F5: ='Modèle de base (CM 2003)'!F5 -> 0 | G5: ='Modèle de base (CM 2003)'!G5 -> 0 | H5: ='Modèle de base (CM 2003)'!H5 -> 0 | I5: ='Modèle de base (CM 2003)'!I5 -> 0 | J5: ='Modèle de base (CM 2003)'!J5 -> 0 | ... M5: ='Modèle de base (CM 2003)'!M5 -> 0
A6: Teneur en or | B6: g/t | C6: ='Modèle de base (CM 2003)'!C6 -> 0 | D6: ='Modèle de base (CM 2003)'!D6 -> 0 | E6: ='Modèle de base (CM 2003)'!E6 -> 0 | F6: ='Modèle de base (CM 2003)'!F6 -> 0 | G6: ='Modèle de base (CM 2003)'!G6 -> 0 | H6: ='Modèle de base (CM 2003)'!H6 -> 0 | I6: ='Modèle de base (CM 2003)'!I6 -> 0 | J6: ='Modèle de base (CM 2003)'!J6 -> 0 | ... M6: ='Modèle de base (CM 2003)'!M6 -> 0
A7: Quantité d'Or Récupéré | B7: oz | C7: ='Modèle de base (CM 2003)'!C7 -> 0 | D7: ='Modèle de base (CM 2003)'!D7 -> 0 | E7: ='Modèle de base (CM 2003)'!E7 -> 191176 | F7: ='Modèle de base (CM 2003)'!F7 -> 215238 | G7: ='Modèle de base (CM 2003)'!G7 -> 189807 | H7: ='Modèle de base (CM 2003)'!H7 -> 168325 | I7: ='Modèle de base (CM 2003)'!I7 -> 210971 | J7: ='Modèle de base (CM 2003)'!J7 -> 167700 | ... M7: ='Modèle de base (CM 2003)'!M7 -> 119370
A8: Cours de l'or | B8: =Q11 -> 1300 | C8: ='Modèle de base (CM 2003)'!C8 -> 0 | D8: ='Modèle de base (CM 2003)'!D8 -> 0 | E8: ='Modèle de base (CM 2003)'!E8 -> 1300 | F8: ='Modèle de base (CM 2003)'!F8 -> 1300 | G8: ='Modèle de base (CM 2003)'!G8 -> 1300 | H8: ='Modèle de base (CM 2003)'!H8 -> 1300 | I8: ='Modèle de base (CM 2003)'!I8 -> 1300 | J8: ='Modèle de base (CM 2003)'!J8 -> 1300 | ... M8: ='Modèle de base (CM 2003)'!M8 -> 1300
A9: Chiffre d'Affaire | B9: $ | C9: =$B$8*C7 -> 0 | D9: =$B$8*D7 -> 0 | E9: =$B$8*E7 -> 248528800 | F9: =$B$8*F7 -> 279809400 | G9: =$B$8*G7 -> 246749100 | H9: =$B$8*H7 -> 218822500 | I9: =$B$8*I7 -> 274262300 | J9: =$B$8*J7 -> 218010000 | ... M9: =$B$8*M7 -> 155181000
A10: Taux de change | B10: 493.00615 | C10: ='Modèle de base (CM 2003)'!C10 -> 0 | D10: ='Modèle de base (CM 2003)'!D10 -> 0 | E10: ='Modèle de base (CM 2003)'!E10 -> 0 | F10: ='Modèle de base (CM 2003)'!F10 -> 0 | G10: ='Modèle de base (CM 2003)'!G10 -> 0 | H10: ='Modèle de base (CM 2003)'!H10 -> 0 | I10: ='Modèle de base (CM 2003)'!I10 -> 0 | J10: ='Modèle de base (CM 2003)'!J10 -> 0 | ... M10: ='Modèle de base (CM 2003)'!M10 -> 0 | Q10: Données | R10: VAN AV IMPÔT | S10: VAN AP IMPÔT | T10: TEMI | U10: TRI AV | V10: TRI AP
A11: Taux d'actualisation | B11: =Q12 -> 0.03 | C11: ='Modèle de base (CM 2003)'!C11 -> 0 | D11: ='Modèle de base (CM 2003)'!D11 -> 0 | E11: ='Modèle de base (CM 2003)'!E11 -> 0 | F11: ='Modèle de base (CM 2003)'!F11 -> 0 | G11: ='Modèle de base (CM 2003)'!G11 -> 0 | H11: ='Modèle de base (CM 2003)'!H11 -> 0 | I11: ='Modèle de base (CM 2003)'!I11 -> 0 | J11: ='Modèle de base (CM 2003)'!J11 -> 0 | ... M11: ='Modèle de base (CM 2003)'!M11 -> 0 | P11: Cours de l'or | Q11: 1300 | R11: =C26 -> 4.3605874e+08 | S11: =C56 -> 1.730842e+08 | T11: =C57 -> 0.60307138 | U11: =C27 -> 0.27738179 | V11: =C58 -> 0.14247931
C12: ='Modèle de base (CM 2003)'!C12 -> 0 | D12: ='Modèle de base (CM 2003)'!D12 -> 0 | E12: ='Modèle de base (CM 2003)'!E12 -> 0 | F12: ='Modèle de base (CM 2003)'!F12 -> 0 | G12: ='Modèle de base (CM 2003)'!G12 -> 0 | H12: ='Modèle de base (CM 2003)'!H12 -> 0 | I12: ='Modèle de base (CM 2003)'!I12 -> 0 | J12: ='Modèle de base (CM 2003)'!J12 -> 0 | ... M12: ='Modèle de base (CM 2003)'!M12 -> 0 | P12: Taux d'actualisation | Q12: 0.03
A13: Coûts d'investissement (CAPEX) | C13: ='Modèle de base (CM 2003)'!C13 -> 0 | D13: ='Modèle de base (CM 2003)'!D13 -> 0 | E13: ='Modèle de base (CM 2003)'!E13 -> 0 | F13: ='Modèle de base (CM 2003)'!F13 -> 0 | G13: ='Modèle de base (CM 2003)'!G13 -> 0 | H13: ='Modèle de base (CM 2003)'!H13 -> 0 | I13: ='Modèle de base (CM 2003)'!I13 -> 0 | J13: ='Modèle de base (CM 2003)'!J13 -> 0 | ... M13: ='Modèle de base (CM 2003)'!M13 -> 0 | P13: IS | Q13: 0.275
